Workbook

Sheet Leadership Summary
A1: Talent 360i | Overall RD Hackfest Inputs – Leadership Submission
A2: Forwarding brief for Devchandra Pandit, Chetan Shetty and Kaushik Upadhyay | Overall Reference Data scope
A4: Executive message
A5: OAC RD foundation inputs are ready for Hackfest use: a 38-competency model covering Admin, Process and Behaviour skills, exact B2–B4 readiness expectations, curated RD learning references, and a governed link to the existing difficulty-tagged question bank. Together, these inputs enable Talent 360i to generate skill- and level-aligned assessments, retain SME approval, identify development needs and support manager-confirmed readiness decisions.
A8: Foundation input | B8: RD contribution | E8: Control / evidence | G8: Talent 360i value
A9: Role and readiness model | B9: 38 competencies: Admin 19, Process 13 and Behaviour 6; B2 17, B3 31 and B4 38 required competencies. | E9: OAC Career Playbook; readiness mix reconciled by formula. | G9: Defines the expected skill breadth and proficiency for each role band.
A10: Skill definitions | B10: Working definitions for every competency, with Beginner, Moderate and Expert expectations. | E10: Technical/process and behavioural assessment methods are separated. | G10: Gives the AI agent governed context for question and evidence generation.
A11: Role–skill matrix | B11: Exact B2/B3/B4 targets and the first band at which each competency becomes required. | E11: Blank means not expected; it must not be scored automatically as a gap. | G11: Enables role-based assessment assignment and level comparison.
A12: SOP and learning mapping | B12: Curated core RD links mapped to each skill and competence target. | E12: SharePoint remains the current content source; links are reviewed by RD SMEs. | G12: Grounds questions, explanations and training recommendations in approved material.
A13: Question bank and difficulty | B13: Faiza Shaikh’s live Question Bank is retained as the source of approved questions and Easy/Medium/Hard tags. | E13: No duplicate question rows; SME status, reviewer and review date remain auditable. | G13: Supports approved-question scheduling while avoiding stale copies and conflicting tags.
A16: Coverage against the Talent 360i MVP
A17: MVP | B17: Requirement | E17: RD workbook support | H17: Governance point
A18: MVP-01 | B18: AI-generated question bank mapped to a selected skill and level. | E18: Skill Master, Role–Skill Matrix, SOP mapping and question-bank ingestion schema. | H18: AI-generated items remain candidates until reviewed.
A19: MVP-02 | B19: Reviewer can edit, approve or reject each question. | E19: SME status, reviewer, rationale, source and review-date fields. | H19: Only Approved questions are assessment eligible.
A20: MVP-03 | B20: Employees receive assessments; results are recorded by person and skill. | E20: Skill_ID, role band, target proficiency and question-type mapping. | H20: Assessment design must reflect the required competence, not difficulty alone.
A21: MVP-04 | B21: System recommends current level and training need for the next level. | E21: Proficiency definitions, target matrix, evidence expectations and learning links. | H21: Expert capability cannot be assigned solely from a question score.
A22: MVP-05 | B22: Leaders can view confirmed skill distribution by team, function or hub. | E22: Formula-driven readiness mix and standardized skill identifiers. | H22: Reporting should use the latest manager-confirmed level.
A23: MVP-07 | B23: Employees attach evidence against a specific skill. | E23: Evidence expectations are defined for each skill family and proficiency decision. | H23: Evidence must stay linked to the assessed skill and level record.
A24: MVP-08 | B24: Managers approve, confirm or send back the assessed level. | E24: Manager validation is mandatory for behavioural and Expert readiness decisions. | H24: Decision, note, approver and timestamp should remain auditable.
A27: Recommended leadership decisions and next actions
A28: # | B28: Action | F28: Owner | H28: Expected output
A29: 1 | B29: Validate the 38-skill wording, target levels and curated learning links as the OAC RD seed model. | F29: Devchandra / RD SMEs | H29: SME-confirmed foundation dataset
A30: 2 | B30: Confirm the ingestion fields and how the live Microsoft List will supply approved questions and difficulty tags. | F30: Chetan / Hackfest team | H30: Agreed technical interface and refresh approach
A31: 3 | B31: Confirm the pilot function, role bands, assessment guardrails and named SME reviewers. | F31: Kaushik / initiative sponsor | H31: Defined pilot scope and accountability
A32: 4 | B32: Align final role terminology and role expectations with the B2–B4 JDs and global career-playbook inputs. | F32: Devika / Performance Excellence | H32: Globally aligned role model
A33: 5 | B33: Approve the first pilot question set, evidence requirements and rollout schedule. | F33: Joint working team | H33: Ready-to-run Talent 360i pilot
A36: Leadership ask: approve this workbook as the OAC RD working seed for the Hackfest prototype, subject to RD SME validation and final role/JD alignment. The live SharePoint learning site and Faiza’s Question Bank should remain the governed content sources.

Sheet Read Me
A1: Talent 360i – Overall Reference Data Hackfest Input Pack
A2: Consolidated RD foundation data for skill readiness, assessment generation, SME approval and development planning | 01 Sep 2026
A4: Package element | B4: What this workbook provides
A5: Scope | B5: Overall Reference Data (not OMNI). The competency model spans Admin, Process and Behaviour capabilities across B2, B3 and B4.
A6: Readiness backbone | B6: Devchandra Pandit’s OAC Career Playbook: exact B2/B3/B4 readiness mix, a dedicated Beginner/Moderate/Expert proficiency framework and the 38-skill matrix.
A7: SOP and learning inputs | B7: Curated core RD links from the Reference Data Learning Home and SOP master; content remains in SharePoint as the live source.
A8: Question inputs | B8: Faiza Shaikh’s Microsoft List remains the authoritative question bank and retains the existing Easy/Medium/Hard tagging. Rows are not duplicated here to prevent version drift.
A9: Assessment design | B9: Technical/process skills: approved questions plus practical evidence. Behaviour/leadership skills: scenarios, evidence and manager validation.
A10: i360 use | B10: Supports AI-generated questions, SME review, role/skill-based assessment, current-level recommendation, training-needs identification and skill-distribution reporting.
A11: Working status | B11: OAC working seed model for Hackfest. Devika’s B2–B4 JDs and global career-playbook inputs should be incorporated during final alignment.
A14: Human-in-the-loop Talent 360i assessment flow
A15: 1. Ingest | B15: 2. Generate | C15: 3. Self-check | D15: 4. SME review | E15: 5. Assess | F15: 6. Recommend | G15: 7. Evidence | H15: 8. Confirm
A16: Roles, skills, levels, SOPs and question bank | B16: Questions mapped to skill and level | C16: Relevance, difficulty, Bloom level and bias | D16: Edit, approve or reject with audit trail | E16: Schedule, respond and score | F16: Current level and TNI | G16: Employee attaches work evidence | H16: Manager confirms level and movement
A19: How to use | B19: Start with Role Skill Matrix → use SOP & Learning Mapping for content grounding → pull live questions/difficulty from Faiza’s List → apply the Question Bank schema for i360 ingestion.
A20: Governance rule | B20: Only SME-approved questions are assessment eligible. Preserve the source difficulty tag unless an SME approves a change; retain reviewer, status and review date.
A21: Key caveat | B21: A question score alone should not establish Expert capability. Expert decisions require complex-case evidence, downstream-impact judgment, coaching/governance evidence and manager confirmation.

Sheet Role Levels
A1: B2–B4 Reference Data Role Levels
A2: Readiness intent and expected competence mix from the OAC Career Playbook
A4: Band | B4: Readiness stage | C4: Role outcome | D4: Total competencies | E4: Beginner | F4: Moderate | G4: Expert | H4: Expert share | I4: Assessment emphasis
A5: B2 | B5: Foundation | C5: Reliable execution; apply core tools and processes; deliver quality with guidance; build confidence and consistency. | D5: 17 | E5: 5 | F5: 10 | G5: 2 | H5: 0.11764706 | I5: Knowledge + standard-case execution + quality evidence; guidance allowed.
A6: B3 | B6: Independent Delivery | C6: Independent ownership; broader and more complex work; solve and improve processes; collaborate across teams. | D6: 31 | E6: 3 | F6: 17 | G6: 11 | H6: 0.35483871 | I6: Independent varied cases + issue diagnosis + improvement/collaboration evidence.
A7: B4 | B7: Leadership & Governance | C7: Set direction and influence stakeholders; coach and scale capability; deliver strategic business outcomes. | D7: 38 | E7: 1 | F7: 4 | G7: 33 | H7: 0.86842105 | I7: Complex/ambiguous cases + governance, coaching, downstream impact and manager confirmation.
A10: Proficiency | B10: Definition | F10: Decision evidence
A11: Beginner | B11: Explains purpose and basic steps; performs standard tasks with guidance or checklist; escalates exceptions. | F11: Higher review required; standard case or guided demonstration.
A12: Moderate | B12: Works independently on standard and varied cases; applies SOP and judgment consistently; documents rationale; meets quality and SLA. | F12: Independent case result, rationale, quality trend and issue handling.
A13: Expert | B13: Handles complex or ambiguous cases; assesses downstream impact; governs or defines standards; coaches others; improves process; acts as SME or approver. | F13: Complex-case evidence, impact judgment, governance/coaching output and manager confirmation.
A14: Not expected | B14: Blank cell in the role-skill matrix means the competency is not a target for that band. | F14: Do not score as a gap unless the role/JD explicitly requires it.

Sheet Proficiency Levels
A1: RD Proficiency Levels – Beginner, Moderate and Expert
A2: Definitions transcribed from the OAC Career Playbook and converted into observable Talent 360i assessment indicators
A4: Important interpretation: proficiency describes the demonstrated level of capability, independence, judgment and impact for a skill. It is not the same as question difficulty. Easy, Medium and Hard are attributes of individual questions; Beginner, Moderate and Expert are readiness decisions based on assessment results, practical evidence and—where required—manager confirmation.
A8: Level_ID | B8: Proficiency | C8: Career-playbook definition | E8: Observable indicators | G8: Assessment evidence | H8: Decision rule | I8: Typical review
A9: PROF_01 | B9: Beginner | C9: Explains the purpose and basic steps; performs standard tasks with guidance or a checklist; escalates exceptions; higher review is required. | E9: • Describes why the task is performed and follows the standard sequence. • Completes routine cases using approved instructions. • Recognises limits and escalates non-standard situations. | G9: Knowledge/application questions plus a guided practical or standard work sample. | H9: Assign Beginner when standard work is demonstrated reliably but guidance or higher review is still needed. | I9: Guidance and higher QC/reviewer oversight
A10: PROF_02 | B10: Moderate | C10: Works independently on standard and varied cases; applies the SOP and judgment consistently; identifies issues and documents rationale; meets quality and SLA expectations. | E10: • Delivers standard and varied cases without routine guidance. • Applies process rules and judgment consistently. • Identifies issues, explains decisions and maintains expected quality/productivity. | G10: Scenario questions plus independent practical evidence, rationale and quality/SLA performance. | H10: Assign Moderate when the person can independently deliver the expected scope and manage normal variations consistently. | I10: Normal quality controls and periodic calibration
A11: PROF_03 | B11: Expert | C11: Handles complex or ambiguous cases; assesses downstream impact; governs or defines standards; coaches others; improves the process; acts as an SME or approver. | E11: • Resolves exceptions and ambiguous cases using evidence. • Evaluates downstream and cross-team impact. • Defines or governs standards, coaches others and leads sustainable improvement. | G11: Complex scenario/case plus work evidence, governance or coaching output and manager/SME confirmation. | H11: Assign Expert only when complex-case judgment and broader impact are demonstrated; a high question score alone is insufficient. | I11: SME calibration and manager confirmation
A14: How Talent 360i should apply the proficiency framework
A15: Step | B15: Application | F15: Control
A16: 1 | B16: Read the target proficiency for the employee’s role and skill from the Role–Skill Matrix. | F16: A blank target means the skill is not expected for that band and should not automatically create a gap.
A17: 2 | B17: Select or generate questions mapped to the skill and intended proficiency; retain the existing question difficulty tag. | F17: SME validates relevance, proficiency alignment, difficulty, rationale and source before approval.
A18: 3 | B18: Score the assessment and review the evidence expected for the proposed proficiency level. | F18: Technical/process skills require practical evidence; behavioural and Expert decisions require broader evidence.
A19: 4 | B19: Recommend the current level and the gap to the next required level, together with relevant learning links. | F19: Recommendation remains provisional until required evidence and manager/SME confirmation are completed.
A20: 5 | B20: Record the confirmed level, development need and review evidence for reporting and movement decisions. | F20: Retain reviewer, decision note, confirmation date and audit history.
A23: Proficiency level versus question difficulty | G23: Career-playbook readiness mix
A24: Dimension | B24: Beginner / Easy | C24: Moderate / Medium | D24: Expert / Hard | E24: Required interpretation | F24: Metric | G24: B2 | H24: B3 | I24: B4
A25: Proficiency | B25: Guided standard execution | C25: Independent varied-case execution | D25: Complex-case leadership and governance | E25: A sustained capability decision for a person and skill | F25: Beginner | G25: =COUNTIF('Role Skill Matrix'!$D$5:$D$42,"Beginner") -> 5 | H25: =COUNTIF('Role Skill Matrix'!$E$5:$E$42,"Beginner") -> 3 | I25: =COUNTIF('Role Skill Matrix'!$F$5:$F$42,"Beginner") -> 1
A26: Question difficulty | B26: One clear rule or direct application | C26: Multiple steps or plausible alternatives | D26: Ambiguity, exceptions, trade-offs or downstream impact | E26: A property of one assessment question | F26: Moderate | G26: =COUNTIF('Role Skill Matrix'!$D$5:$D$42,"Moderate") -> 10 | H26: =COUNTIF('Role Skill Matrix'!$E$5:$E$42,"Moderate") -> 17 | I26: =COUNTIF('Role Skill Matrix'!$F$5:$F$42,"Moderate") -> 4
A27: Guardrail | B27: An Easy question does not automatically prove Beginner readiness. | C27: Medium questions can support Moderate readiness when combined with practical evidence. | D27: Hard questions support Expert evaluation but cannot replace evidence and confirmation. | E27: Never use a one-to-one automatic conversion between difficulty and proficiency. | F27: Expert | G27: =COUNTIF('Role Skill Matrix'!$D$5:$D$42,"Expert") -> 2 | H27: =COUNTIF('Role Skill Matrix'!$E$5:$E$42,"Expert") -> 11 | I27: =COUNTIF('Role Skill Matrix'!$F$5:$F$42,"Expert") -> 33
F28: Total | G28: =SUM(G25:G27) -> 17 | H28: =SUM(H25:H27) -> 31 | I28: =SUM(I25:I27) -> 38
A31: Not expected: a blank cell in the Role–Skill Matrix means the competency is not a target for that band. It should not be recorded as a readiness gap unless the applicable role description explicitly requires the skill.

Sheet Readiness Mix
A1: RD Skill Readiness Mix
A2: Formula-driven reconciliation to the 38-row Role Skill Matrix
A4: Metric | B4: B2 | C4: B3 | D4: B4 | E4: Interpretation
A5: Total competencies | B5: =COUNTIF('Role Skill Matrix'!$D$5:$D$42,"Beginner")+COUNTIF('Role Skill Matrix'!$D$5:$D$42,"Moderate")+COUNTIF('Role Skill Matrix'!$D$5:$D$42,"Expert") -> 17 | C5: =COUNTIF('Role Skill Matrix'!$E$5:$E$42,"Beginner")+COUNTIF('Role Skill Matrix'!$E$5:$E$42,"Moderate")+COUNTIF('Role Skill Matrix'!$E$5:$E$42,"Expert") -> 31 | D5: =COUNTIF('Role Skill Matrix'!$F$5:$F$42,"Beginner")+COUNTIF('Role Skill Matrix'!$F$5:$F$42,"Moderate")+COUNTIF('Role Skill Matrix'!$F$5:$F$42,"Expert") -> 38 | E5: Breadth of role readiness
A6: Beginner | B6: =COUNTIF('Role Skill Matrix'!$D$5:$D$42,"Beginner") -> 5 | C6: =COUNTIF('Role Skill Matrix'!$E$5:$E$42,"Beginner") -> 3 | D6: =COUNTIF('Role Skill Matrix'!$F$5:$F$42,"Beginner") -> 1 | E6: Guided or checklist-based capability
A7: Moderate | B7: =COUNTIF('Role Skill Matrix'!$D$5:$D$42,"Moderate") -> 10 | C7: =COUNTIF('Role Skill Matrix'!$E$5:$E$42,"Moderate") -> 17 | D7: =COUNTIF('Role Skill Matrix'!$F$5:$F$42,"Moderate") -> 4 | E7: Independent standard and varied-case capability
A8: Expert | B8: =COUNTIF('Role Skill Matrix'!$D$5:$D$42,"Expert") -> 2 | C8: =COUNTIF('Role Skill Matrix'!$E$5:$E$42,"Expert") -> 11 | D8: =COUNTIF('Role Skill Matrix'!$F$5:$F$42,"Expert") -> 33 | E8: Complex-case, governance and coaching capability
A9: Expert share | B9: =B8/B5 -> 0.11764706 | C9: =C8/C5 -> 0.35483871 | D9: =D8/D5 -> 0.86842105 | E9: Expert competencies ÷ total competencies
A12: Transition | B12: Admin additions | C12: Process additions | D12: Behaviour additions | E12: Level-ups within existing skills
A13: B2 → B3 | B13: 8 | C13: 5 | D13: 1 | E13: Admin 3 | Process 4 | Behaviour 0
A14: B3 → B4 | B14: 4 | C14: 2 | D14: 1 | E14: Admin 5 | Process 9 | Behaviour 4
A17: Reconciliation check | B17: B2 | C17: B3 | D17: B4 | E17: Expected
A18: Total | B18: =B5 -> 17 | C18: =C5 -> 31 | D18: =D5 -> 38 | E18: 17 / 31 / 38
A19: Beginner | B19: =B6 -> 5 | C19: =C6 -> 3 | D19: =D6 -> 1 | E19: 5 / 3 / 1
A20: Moderate | B20: =B7 -> 10 | C20: =C7 -> 17 | D20: =D7 -> 4 | E20: 10 / 17 / 4
A21: Expert | B21: =B8 -> 2 | C21: =C8 -> 11 | D21: =D8 -> 33 | E21: 2 / 11 / 33

Sheet Skill Master
A1: Overall RD Skill Master and Definitions
A2: Working Hackfest definitions derived from the OAC Career Playbook and grounded in RD learning references
A4: Skill_ID | B4: Family | C4: Skill | D4: Skill definition | E4: Primary assessment method | F4: Evidence expected | G4: Source owner | H4: Status
A5: RD_ADM_01 | B5: Admin | C5: CIP / OGRDS | D5: Use core RD platforms to navigate queues, profiles, search, coding/configuration, reports and governance workflows. | E5: MCQ/scenario + work evidence | F5: Accurate execution/configuration, audit trail, SOP adherence and impact control | G5: Devchandra Pandit / RD SMEs | H5: Working seed
A6: RD_ADM_02 | B6: Admin | C6: EPIC | D6: Manage product imagery used by RD, including retrieval, naming, validation, upload and issue resolution. | E6: MCQ/scenario + work evidence | F6: Accurate execution/configuration, audit trail, SOP adherence and impact control | G6: Devchandra Pandit / RD SMEs | H6: Working seed
A7: RD_ADM_03 | B7: Admin | C7: NIMS | D7: Use item-management and prioritization services and parameters governing workload, item priority, manufacturer/product/sales data, dispatch and compliance. | E7: MCQ/scenario + work evidence | F7: Accurate execution/configuration, audit trail, SOP adherence and impact control | G7: Devchandra Pandit / RD SMEs | H7: Working seed
A8: RD_ADM_04 | B8: Admin | C8: Leaflet | D8: Understand leaflet data flow, inputs, tools and dependencies supporting promotion and leaflet reference data. | E8: MCQ/scenario + work evidence | F8: Accurate execution/configuration, audit trail, SOP adherence and impact control | G8: Devchandra Pandit / RD SMEs | H8: Working seed
A9: RD_ADM_05 | B9: Admin | C9: RCA understanding | D9: Explain quality and operational issues using structured root-cause logic, separate symptom from cause and assess downstream impact. | E9: MCQ/scenario + work evidence | F9: Accurate execution/configuration, audit trail, SOP adherence and impact control | G9: Devchandra Pandit / RD SMEs | H9: Working seed
A10: RD_ADM_06 | B10: Admin | C10: Shared item mgmt. | D10: Manage items and cross-codings shared across countries or markets using ownership, alignment, change control and impact checks. | E10: MCQ/scenario + work evidence | F10: Accurate execution/configuration, audit trail, SOP adherence and impact control | G10: Devchandra Pandit / RD SMEs | H10: Working seed
A11: RD_ADM_07 | B11: Admin | C11: WCP process | D11: Execute Weekly Change Process governance for controlled RD changes, including validation, approval and downstream communication. | E11: MCQ/scenario + work evidence | F11: Accurate execution/configuration, audit trail, SOP adherence and impact control | G11: Devchandra Pandit / RD SMEs | H11: Working seed
A12: RD_ADM_08 | B12: Admin | C12: Work allocation | D12: Allocate work by skill, capacity, priority, SLA and risk; monitor delivery and rebalance when needed. | E12: MCQ/scenario + work evidence | F12: Accurate execution/configuration, audit trail, SOP adherence and impact control | G12: Devchandra Pandit / RD SMEs | H12: Working seed
A13: RD_ADM_09 | B13: Admin | C13: Validation | D13: Validate RD outputs against inputs, rules, schemas/category standards and business requirements. | E13: MCQ/scenario + work evidence | F13: Accurate execution/configuration, audit trail, SOP adherence and impact control | G13: Devchandra Pandit / RD SMEs | H13: Working seed
A14: RD_ADM_10 | B14: Admin | C14: RCA hands-on | D14: Lead data collection, root-cause analysis, corrective and preventive actions and closure evidence. | E14: MCQ/scenario + work evidence | F14: Accurate execution/configuration, audit trail, SOP adherence and impact control | G14: Devchandra Pandit / RD SMEs | H14: Working seed
A15: RD_ADM_11 | B15: Admin | C15: Validation checks | D15: Design and run targeted checks to detect missing, inconsistent or invalid data and confirm correction. | E15: MCQ/scenario + work evidence | F15: Accurate execution/configuration, audit trail, SOP adherence and impact control | G15: Devchandra Pandit / RD SMEs | H15: Working seed
... A42: RD_BEH_06 | B42: Behaviour | C42: Continuous learning | D42: Keep skills current, seek feedback, apply learning and share knowledge. | E42: Scenario + evidence + manager validation | F42: Observable behaviour, outcome, stakeholder/manager confirmation | G42: Devchandra Pandit / RD SMEs | H42: Working seed

Sheet Role Skill Matrix
A1: Overall RD Role–Skill Matrix
A2: Exact band targets transcribed from the OAC Career Playbook; blank means not expected at that band
A4: Skill_ID | B4: Family | C4: Skill | D4: B2 target | E4: B3 target | F4: B4 target | G4: First required band | H4: Progression
A5: RD_ADM_01 | B5: Admin | C5: CIP / OGRDS | D5: Moderate | E5: Expert | F5: Expert | G5: B2 | H5: B2 Moderate → B3 Expert → B4 Expert
A6: RD_ADM_02 | B6: Admin | C6: EPIC | D6: Moderate | E6: Expert | F6: Expert | G6: B2 | H6: B2 Moderate → B3 Expert → B4 Expert
A7: RD_ADM_03 | B7: Admin | C7: NIMS | D7: Beginner | E7: Moderate | F7: Expert | G7: B2 | H7: B2 Beginner → B3 Moderate → B4 Expert
A8: RD_ADM_04 | B8: Admin | C8: Leaflet | D8: Beginner | E8: Beginner | F8: Beginner | G8: B2 | H8: B2 Beginner → B3 Beginner → B4 Beginner
A9: RD_ADM_05 | B9: Admin | C9: RCA understanding | D9: Moderate | E9: Moderate | F9: Expert | G9: B2 | H9: B2 Moderate → B3 Moderate → B4 Expert
A10: RD_ADM_06 | B10: Admin | C10: Shared item mgmt. | D10: Expert | E10: Expert | F10: Expert | G10: B2 | H10: B2 Expert → B3 Expert → B4 Expert
A11: RD_ADM_07 | B11: Admin | C11: WCP process | D11: Expert | E11: Expert | F11: Expert | G11: B2 | H11: B2 Expert → B3 Expert → B4 Expert
A12: RD_ADM_08 | B12: Admin | C12: Work allocation | E12: Expert | F12: Expert | G12: B3 | H12: B3 Expert → B4 Expert
A13: RD_ADM_09 | B13: Admin | C13: Validation | E13: Moderate | F13: Expert | G13: B3 | H13: B3 Moderate → B4 Expert
A14: RD_ADM_10 | B14: Admin | C14: RCA hands-on | E14: Moderate | F14: Expert | G14: B3 | H14: B3 Moderate → B4 Expert
A15: RD_ADM_11 | B15: Admin | C15: Validation checks | E15: Moderate | F15: Expert | G15: B3 | H15: B3 Moderate → B4 Expert
A16: RD_ADM_12 | B16: Admin | C16: Validation feedback | E16: Expert | F16: Expert | G16: B3 | H16: B3 Expert → B4 Expert
A17: RD_ADM_13 | B17: Admin | C17: Task training | E17: Expert | F17: Expert | G17: B3 | H17: B3 Expert → B4 Expert
A18: RD_ADM_14 | B18: Admin | C18: OGRDS refresher | E18: Expert | F18: Expert | G18: B3 | H18: B3 Expert → B4 Expert
A19: RD_ADM_15 | B19: Admin | C19: File prep | E19: Expert | F19: Expert | G19: B3 | H19: B3 Expert → B4 Expert
A20: RD_ADM_16 | B20: Admin | C20: Project alignment | F20: Expert | G20: B4 | H20: B4 Expert
A21: RD_ADM_17 | B21: Admin | C21: Rule set browser | F21: Expert | G21: B4 | H21: B4 Expert
A22: RD_ADM_18 | B22: Admin | C22: Validation rule creation | F22: Expert | G22: B4 | H22: B4 Expert
A23: RD_ADM_19 | B23: Admin | C23: Country workflow setup | F23: Expert | G23: B4 | H23: B4 Expert
A24: RD_PRO_01 | B24: Process | C24: Item Coding | D24: Moderate | E24: Moderate | F24: Expert | G24: B2 | H24: B2 Moderate → B3 Moderate → B4 Expert
A25: RD_PRO_02 | B25: Process | C25: Cross Coding | D25: Moderate | E25: Expert | F25: Expert | G25: B2 | H25: B2 Moderate → B3 Expert → B4 Expert
A26: RD_PRO_03 | B26: Process | C26: Validation browser | D26: Beginner | E26: Moderate | F26: Expert | G26: B2 | H26: B2 Beginner → B3 Moderate → B4 Expert
A27: RD_PRO_04 | B27: Process | C27: Report extraction | D27: Beginner | E27: Moderate | F27: Expert | G27: B2 | H27: B2 Beginner → B3 Moderate → B4 Expert
A28: RD_PRO_05 | B28: Process | C28: Leaflet Coding | D28: Beginner | E28: Beginner | F28: Moderate | G28: B2 | H28: B2 Beginner → B3 Beginner → B4 Moderate
A29: RD_PRO_06 | B29: Process | C29: Char Population | D29: Moderate | E29: Expert | F29: Expert | G29: B2 | H29: B2 Moderate → B3 Expert → B4 Expert
A30: RD_PRO_07 | B30: Process | C30: OGRDS Surgery | E30: Beginner | F30: Moderate | G30: B3 | H30: B3 Beginner → B4 Moderate
A31: RD_PRO_08 | B31: Process | C31: GCC Toolbox | E31: Moderate | F31: Expert | G31: B3 | H31: B3 Moderate → B4 Expert
A32: RD_PRO_09 | B32: Process | C32: Proposal browser | E32: Moderate | F32: Expert | G32: B3 | H32: B3 Moderate → B4 Expert
A33: RD_PRO_10 | B33: Process | C33: Rejection browser | E33: Moderate | F33: Expert | G33: B3 | H33: B3 Moderate → B4 Expert
A34: RD_PRO_11 | B34: Process | C34: Potential reuse browser | E34: Moderate | F34: Expert | G34: B3 | H34: B3 Moderate → B4 Expert
A35: RD_PRO_12 | B35: Process | C35: EIM rules (offline) | F35: Moderate | G35: B4 | H35: B4 Moderate
A36: RD_PRO_13 | B36: Process | C36: Fuzzy lookup | F36: Expert | G36: B4 | H36: B4 Expert
A37: RD_BEH_01 | B37: Behaviour | C37: Problem solving / AI | D37: Moderate | E37: Moderate | F37: Expert | G37: B2 | H37: B2 Moderate → B3 Moderate → B4 Expert
A38: RD_BEH_02 | B38: Behaviour | C38: Analytical skills | D38: Moderate | E38: Moderate | F38: Expert | G38: B2 | H38: B2 Moderate → B3 Moderate → B4 Expert
A39: RD_BEH_03 | B39: Behaviour | C39: Attention to detail | D39: Moderate | E39: Moderate | F39: Expert | G39: B2 | H39: B2 Moderate → B3 Moderate → B4 Expert
A40: RD_BEH_04 | B40: Behaviour | C40: Business communication | D40: Moderate | E40: Moderate | F40: Expert | G40: B2 | H40: B2 Moderate → B3 Moderate → B4 Expert
A41: RD_BEH_05 | B41: Behaviour | C41: Cross-team collaboration | E41: Moderate | F41: Moderate | G41: B3 | H41: B3 Moderate → B4 Moderate
...

Sheet SOP & Learning Mapping
A1: Curated Core RD SOP and Learning Mapping
A2: Links only: current content remains in the Reference Data Learning site. Mapping follows each skill’s first required band and competence target.
A4: Skill_ID | B4: Family | C4: Skill | D4: B2 | E4: B3 | F4: B4 | G4: Reference title | H4: Source type | I4: Primary URL | J4: Mapping note | K4: Owner | L4: Review status
A5: RD_ADM_01 | B5: Admin | C5: CIP / OGRDS | D5: Moderate | E5: Expert | F5: Expert | G5: OGRDS Introduction | H5: SOP / learning | I5: https://nielsenenterprise.sharepoint.com/sites/globalreferencedata/Shared Documents/OGRDS/Overviews/OGRDS Introduction.pptx?web=1 | J5: Core platform orientation; pair with navigation, security and current release material. | K5: RD Learning / Process SME | L5: Curated for Hackfest
A6: RD_ADM_02 | B6: Admin | C6: EPIC | D6: Moderate | E6: Expert | F6: Expert | G6: Global ePics User Guide | H6: User guide | I6: https://nielsenenterprise.sharepoint.com/sites/globalreferencedata/Shared Documents/EPICS/Global ePics - User Guide.pptx?web=1 | J6: Core EPIC workflow and operating guidance. | K6: RD Learning / Process SME | L6: Curated for Hackfest
A7: RD_ADM_03 | B7: Admin | C7: NIMS | D7: Beginner | E7: Moderate | F7: Expert | G7: NIMS Overall Process | H7: SOP catalogue | I7: https://nielsenenterprise.sharepoint.com/sites/globalreferencedata/Shared Documents/SOP - Full List.xlsx?web=1 | J7: Open the SOP master and filter for NIMS Overall Process. | K7: RD Learning / Process SME | L7: Curated for Hackfest
A8: RD_ADM_04 | B8: Admin | C8: Leaflet | D8: Beginner | E8: Beginner | F8: Beginner | G8: Leaflet process and training | H8: Learning catalogue | I8: https://nielsenenterprise.sharepoint.com/sites/globalreferencedata/SitePages/ogrds.aspx?OR=Teams-HL&CT=1686282924288&clickparams=eyJBcHBOYW1lIjoiVGVhbXMtRGVza3RvcCIsIkFwcFZlcnNpb24iOiIyNy8yMzA1MDEwMDQyMiIsIkhhc0ZlZGVyYXRlZFVzZXIiOmZhbHNlfQ%3D%3D | J8: Use the Leaflet learning path available from the RD Learning Home. | K8: RD Learning / Process SME | L8: Curated for Hackfest
A9: RD_ADM_05 | B9: Admin | C9: RCA understanding | D9: Moderate | E9: Moderate | F9: Expert | G9: Evidence-based RCA scenario | H9: Evidence / manager validation | J9: Assess through a structured scenario plus documented operational evidence. | K9: RD Learning / Process SME | L9: Curated for Hackfest
A10: RD_ADM_06 | B10: Admin | C10: Shared item mgmt. | D10: Expert | E10: Expert | F10: Expert | G10: OGRDS – Retailer Data Management | H10: Training | I10: https://nielsenenterprise.sharepoint.com/sites/globalreferencedata/Shared Documents/OGRDS/Cross Coding/OGRDS - Retailer Data Management.pptx?web=1 | J10: Supports shared ownership, retailer data and cross-country impact concepts. | K10: RD Learning / Process SME | L10: Curated for Hackfest
A11: RD_ADM_07 | B11: Admin | C11: WCP process | D11: Expert | E11: Expert | F11: Expert | G11: SOP – OGRDS Weekly Change Process | H11: SOP | I11: https://nielsenenterprise.sharepoint.com/sites/globalreferencedata/Shared Documents/OGRDS/Generic Characteristics/SOP - OGRDS Weekly Change Process.pptx?web=1 | J11: Controlled-change governance and weekly process. | K11: RD Learning / Process SME | L11: Curated for Hackfest
A12: RD_ADM_08 | B12: Admin | C12: Work allocation | E12: Expert | F12: Expert | G12: Automatic Work Allocation | H12: Training | I12: https://nielsenenterprise.sharepoint.com/sites/globalreferencedata/Shared Documents/OGRDS/Country Coding Configuration/Automatic Work Allocation.pptx?web=1 | J12: Configuration and allocation mechanics; add local operating evidence for leadership bands. | K12: RD Learning / Process SME | L12: Curated for Hackfest
A13: RD_ADM_09 | B13: Admin | C13: Validation | E13: Moderate | F13: Expert | G13: Configuration – Validation Rules Toolbox | H13: Training | I13: https://nielsenenterprise.sharepoint.com/sites/globalreferencedata/Shared Documents/OGRDS/Country Coding Configuration/Configuration - Validation Rules Toolbox.pptx?web=1 | J13: Core validation logic and configuration reference. | K13: RD Learning / Process SME | L13: Curated for Hackfest
A14: RD_ADM_10 | B14: Admin | C14: RCA hands-on | E14: Moderate | F14: Expert | G14: RCA case and closure evidence | H14: Evidence / manager validation | J14: Assess completed RCA, actions and closure evidence rather than recall alone. | K14: RD Learning / Process SME | L14: Curated for Hackfest
A15: RD_ADM_11 | B15: Admin | C15: Validation checks | E15: Moderate | F15: Expert | G15: Configuration – Validation Rules Toolbox | H15: Training | I15: https://nielsenenterprise.sharepoint.com/sites/globalreferencedata/Shared Documents/OGRDS/Country Coding Configuration/Configuration - Validation Rules Toolbox.pptx?web=1 | J15: Apply checks to representative RD outputs and exceptions. | K15: RD Learning / Process SME | L15: Curated for Hackfest
A16: RD_ADM_12 | B16: Admin | C16: Validation feedback | E16: Expert | F16: Expert | G16: RD Proof of Execution SOP | H16: SOP | I16: https://nielsenenterprise.sharepoint.com/sites/globalreferencedata/Shared Documents/OGRDS/Query Management/RD Proof of Execution_SOP.docx?web=1 | J16: Use alongside reviewed feedback records and closure evidence. | K16: RD Learning / Process SME | L16: Curated for Hackfest
A17: RD_ADM_13 | B17: Admin | C17: Task training | E17: Expert | F17: Expert | G17: OGRDS Cross & Char Coding – Training Plan | H17: Training plan | I17: https://nielsenenterprise.sharepoint.com/sites/globalreferencedata/Shared Documents/Training Plans/OGRDS Cross & Char coding - Training Plan.xlsx?web=1 | J17: Use as a model for task-based learning, practice and proficiency checks. | K17: RD Learning / Process SME | L17: Curated for Hackfest
A18: RD_ADM_14 | B18: Admin | C18: OGRDS refresher | E18: Expert | F18: Expert | G18: OGRDS M26.7 Release Overview and Documentation | H18: Release refresher | I18: https://nielsenenterprise.sharepoint.com/sites/globalreferencedata/Shared Documents/New Releases/OGRDS/2026/OGRDS_PnB_Release M26.7_Overview and Documentation.pptx?web=1 | J18: Latest located release pack; retain a current-release check at use time. | K18: RD Learning / Process SME | L18: Curated for Hackfest
A19: RD_ADM_15 | B19: Admin | C19: File prep | E19: Expert | F19: Expert | G19: OGRDS Surgery and Extracts | H19: Training | I19: https://nielsenenterprise.sharepoint.com/sites/globalreferencedata/Shared Documents/OGRDS/Report, Surgery & Publications/OGRDS Surgery and Extracts.pptx?web=1 | J19: Covers structured preparation for extracts and controlled changes. | K19: RD Learning / Process SME | L19: Curated for Hackfest
A20: RD_ADM_16 | B20: Admin | C20: Project alignment | F20: Expert | G20: Reference Data Learning Home | H20: Learning catalogue | I20: https://nielsenenterprise.sharepoint.com/sites/globalreferencedata/SitePages/ogrds.aspx?OR=Teams-HL&CT=1686282924288&clickparams=eyJBcHBOYW1lIjoiVGVhbXMtRGVza3RvcCIsIkFwcFZlcnNpb24iOiIyNy8yMzA1MDEwMDQyMiIsIkhhc0ZlZGVyYXRlZFVzZXIiOmZhbHNlfQ%3D%3D | J20: Use current governance/project resources plus project artefacts for evidence. | K20: RD Learning / Process SME | L20: Curated for Hackfest
A21: RD_ADM_17 | B21: Admin | C21: Rule set browser | F21: Expert | G21: Rule Set Browser – Rule Set Maintenance | H21: Training | I21: https://nielsenenterprise.sharepoint.com/sites/globalreferencedata/Shared Documents/OGRDS/Characteristics Management/Rule Set Browser - Rule Set Maintenance.pptx?web=1 | J21: Rule-set review, maintenance, impact assessment and testing. | K21: RD Learning / Process SME | L21: Curated for Hackfest
A22: RD_ADM_18 | B22: Admin | C22: Validation rule creation | F22: Expert | G22: Configuration – Validation Rules Toolbox | H22: Training | I22: https://nielsenenterprise.sharepoint.com/sites/globalreferencedata/Shared Documents/OGRDS/Country Coding Configuration/Configuration - Validation Rules Toolbox.pptx?web=1 | J22: Design, scope, test and govern validation rules. | K22: RD Learning / Process SME | L22: Curated for Hackfest
A23: RD_ADM_19 | B23: Admin | C23: Country workflow setup | F23: Expert | G23: OGRDS Coding Models and Workflow Overview | H23: Training | I23: https://nielsenenterprise.sharepoint.com/sites/globalreferencedata/Shared Documents/OGRDS/Overviews/OGRDS Coding Models and Workflow Overview.pptx?web=1 | J23: Pair with the Country Coding Configuration Workflow deck when configuring a country. | K23: RD Learning / Process SME | L23: Curated for Hackfest
A24: RD_PRO_01 | B24: Process | C24: Item Coding | D24: Moderate | E24: Moderate | F24: Expert | G24: SOP – Item Coding | H24: SOP | I24: https://nielsenenterprise.sharepoint.com/sites/globalreferencedata/Shared Documents/OGRDS/Item Coding/SOP_Item Coding.docx?web=1 | J24: Primary process reference for item creation and maintenance. | K24: RD Learning / Process SME | L24: Curated for Hackfest
A25: RD_PRO_02 | B25: Process | C25: Cross Coding | D25: Moderate | E25: Expert | F25: Expert | G25: SOP – Cross Coding | H25: SOP | I25: https://nielsenenterprise.sharepoint.com/sites/globalreferencedata/Shared Documents/OGRDS/Cross Coding/SOP_Cross coding.docx?web=1 | J25: Primary process reference; pair with Cross Coding Fields E2E where needed. | K25: RD Learning / Process SME | L25: Curated for Hackfest
A26: RD_PRO_03 | B26: Process | C26: Validation browser | D26: Beginner | E26: Moderate | F26: Expert | G26: Configuration – Validation Rules Toolbox | H26: Training | I26: https://nielsenenterprise.sharepoint.com/sites/globalreferencedata/Shared Documents/OGRDS/Country Coding Configuration/Configuration - Validation Rules Toolbox.pptx?web=1 | J26: Use for exception review and validation work items. | K26: RD Learning / Process SME | L26: Curated for Hackfest
A27: RD_PRO_04 | B27: Process | C27: Report extraction | D27: Beginner | E27: Moderate | F27: Expert | G27: OGRDS Reports | H27: Training | I27: https://nielsenenterprise.sharepoint.com/sites/globalreferencedata/Shared Documents/OGRDS/Report, Surgery & Publications/OGRDS Reports.pptx?web=1 | J27: Report selection, execution and interpretation; catalogue also lists available reports. | K27: RD Learning / Process SME | L27: Curated for Hackfest
A28: RD_PRO_05 | B28: Process | C28: Leaflet Coding | D28: Beginner | E28: Beginner | F28: Moderate | G28: Leaflet coding learning path | H28: Learning catalogue | I28: https://nielsenenterprise.sharepoint.com/sites/globalreferencedata/SitePages/ogrds.aspx?OR=Teams-HL&CT=1686282924288&clickparams=eyJBcHBOYW1lIjoiVGVhbXMtRGVza3RvcCIsIkFwcFZlcnNpb24iOiIyNy8yMzA1MDEwMDQyMiIsIkhhc0ZlZGVyYXRlZFVzZXIiOmZhbHNlfQ%3D%3D | J28: Use the current Leaflet learning path and country-specific operating notes. | K28: RD Learning / Process SME | L28: Curated for Hackfest
A29: RD_PRO_06 | B29: Process | C29: Char Population | D29: Moderate | E29: Expert | F29: Expert | G29: SOP – Item Coding | H29: SOP | I29: https://nielsenenterprise.sharepoint.com/sites/globalreferencedata/Shared Documents/OGRDS/Item Coding/SOP_Item Coding.docx?web=1 | J29: Pair with the Cross & Char Coding Training Plan for characteristic practice. | K29: RD Learning / Process SME | L29: Curated for Hackfest
A30: RD_PRO_07 | B30: Process | C30: OGRDS Surgery | E30: Beginner | F30: Moderate | G30: OGRDS Surgery 01 – General | H30: Training | I30: https://nielsenenterprise.sharepoint.com/sites/globalreferencedata/Shared Documents/OGRDS/Report, Surgery & Publications/OGRDS Surgery 01 - General.pptx?web=1 | J30: General controlled bulk-change workflow and result validation. | K30: RD Learning / Process SME | L30: Curated for Hackfest
A31: RD_PRO_08 | B31: Process | C31: GCC Toolbox | E31: Moderate | F31: Expert | G31: GCC Toolbox learning resources | H31: Learning catalogue | I31: https://nielsenenterprise.sharepoint.com/sites/globalreferencedata/SitePages/ogrds.aspx?OR=Teams-HL&CT=1686282924288&clickparams=eyJBcHBOYW1lIjoiVGVhbXMtRGVza3RvcCIsIkFwcFZlcnNpb24iOiIyNy8yMzA1MDEwMDQyMiIsIkhhc0ZlZGVyYXRlZFVzZXIiOmZhbHNlfQ%3D%3D | J31: Navigate to GCC resources from the RD Learning Home; confirm current tool guidance. | K31: RD Learning / Process SME | L31: Curated for Hackfest
A32: RD_PRO_09 | B32: Process | C32: Proposal browser | E32: Moderate | F32: Expert | G32: OGRDS Proposal Management – Value Administration | H32: Training | I32: https://nielsenenterprise.sharepoint.com/sites/globalreferencedata/Shared Documents/OGRDS/Proposal Management/OGRDS PROP MAN FUNCT - Value Administration.pptx?web=1 | J32: Governed value and configuration proposal handling. | K32: RD Learning / Process SME | L32: Curated for Hackfest
A33: RD_PRO_10 | B33: Process | C33: Rejection browser | E33: Moderate | F33: Expert | G33: Item Rejection Browser | H33: Training | I33: https://nielsenenterprise.sharepoint.com/sites/globalreferencedata/Shared Documents/OGRDS/Item Coding/Item Rejection Browser.pptx?web=1 | J33: Diagnosis, correction and reprocessing of rejected items. | K33: RD Learning / Process SME | L33: Curated for Hackfest
A34: RD_PRO_11 | B34: Process | C34: Potential reuse browser | E34: Moderate | F34: Expert | G34: OGRDS Potentially Reused Browser | H34: Training | I34: https://nielsenenterprise.sharepoint.com/sites/globalreferencedata/Shared Documents/OGRDS/Item Coding/OGRDS Potentially Reused Browser.pptx?web=1 | J34: Reuse decision workflow and duplicate-risk control. | K34: RD Learning / Process SME | L34: Curated for Hackfest
A35: RD_PRO_12 | B35: Process | C35: EIM rules (offline) | F35: Moderate | G35: Configuration – External Input Mapping | H35: Training | I35: https://nielsenenterprise.sharepoint.com/sites/globalreferencedata/Shared Documents/OGRDS/Country Coding Configuration/Configuration - External Input Mapping.pptx?web=1 | J35: Offline mapping configuration and impact validation. | K35: RD Learning / Process SME | L35: Curated for Hackfest
A36: RD_PRO_13 | B36: Process | C36: Fuzzy lookup | F36: Expert | G36: Fuzzy Lookup learning resource | H36: SOP catalogue | I36: https://nielsenenterprise.sharepoint.com/sites/globalreferencedata/Shared Documents/SOP - Full List.xlsx?web=1 | J36: Open the SOP master and filter for the current Fuzzy Lookup resource. | K36: RD Learning / Process SME | L36: Curated for Hackfest
A37: RD_BEH_01 | B37: Behaviour | C37: Problem solving / AI | D37: Moderate | E37: Moderate | F37: Expert | G37: Scenario, work sample and manager validation | H37: Evidence / manager validation | J37: Use a realistic RD problem; assess judgment, responsible AI use and outcome quality. | K37: RD Learning / Process SME | L37: Curated for Hackfest
A38: RD_BEH_02 | B38: Behaviour | C38: Analytical skills | D38: Moderate | E38: Moderate | F38: Expert | G38: Data scenario and work evidence | H38: Evidence / manager validation | J38: Assess analysis logic, assumptions, impact and conclusion quality. | K38: RD Learning / Process SME | L38: Curated for Hackfest
A39: RD_BEH_03 | B39: Behaviour | C39: Attention to detail | D39: Moderate | E39: Moderate | F39: Expert | G39: Quality evidence and observation | H39: Evidence / manager validation | J39: Use quality trend, error detection and complete evidence rather than knowledge recall only. | K39: RD Learning / Process SME | L39: Curated for Hackfest
A40: RD_BEH_04 | B40: Behaviour | C40: Business communication | D40: Moderate | E40: Moderate | F40: Expert | G40: Communication sample and stakeholder evidence | H40: Evidence / manager validation | J40: Assess clarity, audience fit, risk communication and action orientation. | K40: RD Learning / Process SME | L40: Curated for Hackfest
A41: RD_BEH_05 | B41: Behaviour | C41: Cross-team collaboration | E41: Moderate | F41: Moderate | G41: Cross-team delivery evidence | H41: Evidence / manager validation | J41: Assess stakeholder feedback, dependency resolution and shared outcomes. | K41: RD Learning / Process SME | L41: Curated for Hackfest
...

Sheet Question Bank & Difficulty
A1: Question Bank and Difficulty – i360 Interface
A2: Faiza Shaikh’s Microsoft List is the live source of truth for RD test questions and the existing difficulty marking
A4: Authoritative source | B4: Faiza Shaikh – Question Bank – All Items
A5: Live URL | B5: https://nielsenenterprise.sharepoint.com/sites/Faizashaikh/Lists/Questionnaire%20bank/AllItems.aspx?env=WebViewList&ct=1788235712623&or=Teams-HL&LOF=1
A6: Use rule | B6: Pull current approved rows and retain the existing difficulty tag. Do not maintain a duplicate question bank in this workbook.
A7: i360 control | B7: AI may generate or propose questions, but only SME-approved questions are eligible for assessment; review status must remain auditable.
A10: Required ingestion field | B10: Requirement | C10: Purpose in Talent 360i | E10: Difficulty | F10: Expected demand | G10: Typical evidence | H10: Tagging guardrail
A11: Question_ID | B11: Required; stable unique identifier | C11: Audit, review history and assessment traceability | E11: Easy | F11: Recall, identify or apply one clear rule in a standard case. | G11: Basic concept, direct SOP step, one unambiguous choice. | H11: Do not equate Easy with Beginner proficiency automatically; confirm the skill-level intent.
A12: Question_Text | B12: Required | C12: Question presented to learner | E12: Medium | F12: Apply multiple steps or choose among plausible options in a varied case. | G12: Judgment using SOP, moderate ambiguity, rationale or sequence required. | H12: Recommended default for independent-delivery checks after SME calibration.
A13: Option_A to Option_D | B13: Required for MCQ | C13: Response options; add fewer/more fields only if question type requires | E13: Hard | F13: Resolve complex or ambiguous situations, trade-offs, exceptions or downstream impact. | G13: Multi-source reasoning, exception handling, governance/impact decision. | H13: Hard questions support Expert assessment but do not replace work evidence and manager confirmation.
A14: Correct_Answer | B14: Required for scored objective items | C14: Automated scoring and SME review
A15: Skill_ID | B15: Required; map to Skill Master | C15: Skill-level assessment and reporting
A16: Difficulty | B16: Required; preserve existing Easy/Medium/Hard tag | C16: Difficulty mix, validation and assessment design | E16: Step | F16: Actor | G16: Decision | H16: Audit output
A17: Proficiency_Level | B17: Required: Beginner/Moderate/Expert | C17: Map question to career-playbook expectation | E17: 1. Source / generate | F17: RD SME or AI agent | G17: Create candidate mapped to skill and level | H17: Draft question + source reference
A18: Question_Type | B18: Required: MCQ/scenario/case/evidence | C18: Select scoring and review method | E18: 2. Self-check | F18: AI agent | G18: Check relevance, difficulty, Bloom demand, bias and sensitivity | H18: Validation flags
A19: Rationale | B19: Required before final approval | C19: Explain correct answer and support SME quality review | E19: 3. SME review | F19: Named RD SME | G19: Edit, approve or reject | H19: Status, comments, reviewer and date
A20: Source_Reference | B20: Required | C20: SOP/learning link or evidence basis | E20: 4. Assess | F20: Talent 360i | G20: Schedule from Approved questions only | H20: Assessment, responses and score
A21: SME_Status | B21: Required: Draft/Edit/Approved/Rejected | C21: Only Approved is assessment eligible | E21: 5. Confirm | F21: Manager / evidence reviewer | G21: Confirm level using score plus evidence | H21: Confirmed level, TNI and movement record
A22: SME_Reviewer | B22: Required for Approved | C22: Accountability for question approval
A23: Last_Reviewed | B23: Required for Approved | C23: Freshness and auditability

Sheet Source Register
A1: Source Register and Ownership
A2: Audit trail for the Hackfest input pack; SharePoint/List content remains authoritative and should be checked for updates
A4: Source_ID | B4: Source | C4: Purpose | D4: Owner | E4: Location / URL | F4: Status | G4: As of | H4: Usage note
A5: SRC_01 | B5: OAC Career Playbook(1).pptx | C5: Readiness mix, proficiency levels and 38-skill B2–B4 matrix | D5: Devchandra Pandit | E5: Attached working source | F5: Working OAC seed | G5: 2026-09-01 | H5: Basis for Role Levels, Readiness Mix, Skill Master and Role Skill Matrix.
A6: SRC_02 | B6: Reference Data Learning Home | C6: Primary navigation for current RD SOPs and learning resources | D6: Global Reference Data Learning | E6: https://nielsenenterprise.sharepoint.com/sites/globalreferencedata/SitePages/ogrds.aspx?OR=Teams-HL&CT=1686282924288&clickparams=eyJBcHBOYW1lIjoiVGVhbXMtRGVza3RvcCIsIkFwcFZlcnNpb24iOiIyNy8yMzA1MDEwMDQyMiIsIkhhc0ZlZGVyYXRlZFVzZXIiOmZhbHNlfQ%3D%3D | F6: Live source | G6: 2026-09-01 | H6: Use for current material; linked content may be updated after this pack.
A7: SRC_03 | B7: SOP – Full List.xlsx | C7: Master list used when a direct learning asset link was not located | D7: Global Reference Data Learning | E7: https://nielsenenterprise.sharepoint.com/sites/globalreferencedata/Shared Documents/SOP - Full List.xlsx?web=1 | F7: Live source | G7: 2026-08-31 | H7: Filter by reference title, especially NIMS and Fuzzy Lookup.
A8: SRC_04 | B8: Faiza Shaikh – Question Bank – All Items | C8: Live RD test questions and existing difficulty classification | D8: Faiza Shaikh | E8: https://nielsenenterprise.sharepoint.com/sites/Faizashaikh/Lists/Questionnaire%20bank/AllItems.aspx?env=WebViewList&ct=1788235712623&or=Teams-HL&LOF=1 | F8: Authoritative question source | G8: 2026-09-01 | H8: Do not duplicate rows; pull current Approved items for assessment generation.
A9: SRC_05 | B9: Talent 360i – Operations Problem Statement | C9: MVP outcomes, human-in-the-loop workflow and success criteria | D9: Hackfest team | E9: Embedded in Talent 360i Reference | F9: Hackfest input | G9: 2026-09-01 | H9: Used to shape workbook interface, MVP mapping and controls.
A10: SRC_06 | B10: SkillPath AI – Talent 360i sample architecture | C10: Foundation data, AI/SME workflow, dataset structure and expected outputs | D10: Hackfest team | E10: Embedded in Talent 360i Reference | F10: Hackfest input | G10: 2026-09-01 | H10: Used for ingestion schema, governance design and leadership mapping.
A11: SRC_07 | B11: Kaushik Upadhyay – Hackfest inputs email | C11: Requested RD SOPs, recent PKT questions, difficulty classification and skill definitions/matrix | D11: Kaushik Upadhyay | E11: Provided email screenshot | F11: Request record | G11: 2026-08-30 | H11: Defines deliverable scope; Devika handles B2–B4 JDs/global playbook inputs.

Sheet Talent 360i Reference
A1: Talent 360i – Hackfest Reference Visuals
A2: Source visuals supplied with the RD input request; included for context and onward sharing
A4: Reference 1 | Operations problem statement, expected MVP outcomes and success criteria
A40: Reference 2 | SkillPath AI / Talent 360i sample architecture and dataset structure
A84: Working interpretation for OAC RD: the workbook provides the role/skill foundation, target proficiency, curated learning mapping, governed live question-bank interface and human-validation controls required to seed the Talent 360i prototype.
